[2020-08-18 07:36:47,590][uWSGIWorker1Core0:140159770849152][task_id:main.views][views.py:239][ERROR][Exception at doAdminAction: name 'acitonid' is not defined]
[2020-08-18 07:36:47,630][uWSGIWorker1Core0:140159770849152][task_id:django.request][log.py:224][ERROR][Internal Server Error: /admin_action]
Traceback (most recent call last):
  File "/usr/local/lib64/python3.8/site-packages/django/core/handlers/exception.py", line 47, in inner
    response = get_response(request)
  File "/usr/local/lib64/python3.8/site-packages/django/core/handlers/base.py", line 186, in _get_response
    self.check_response(response, callback)
  File "/usr/local/lib64/python3.8/site-packages/django/core/handlers/base.py", line 307, in check_response
    raise ValueError(
ValueError: The view main.views.doAdminAction didn't return an HttpResponse object. It returned None instead.
[2020-08-18 07:36:50,439][uWSGIWorker1Core0:140159770849152][task_id:main.views][views.py:239][ERROR][Exception at doAdminAction: name 'acitonid' is not defined]
[2020-08-18 07:36:50,460][uWSGIWorker1Core0:140159770849152][task_id:django.request][log.py:224][ERROR][Internal Server Error: /admin_action]
Traceback (most recent call last):
  File "/usr/local/lib64/python3.8/site-packages/django/core/handlers/exception.py", line 47, in inner
    response = get_response(request)
  File "/usr/local/lib64/python3.8/site-packages/django/core/handlers/base.py", line 186, in _get_response
    self.check_response(response, callback)
  File "/usr/local/lib64/python3.8/site-packages/django/core/handlers/base.py", line 307, in check_response
    raise ValueError(
ValueError: The view main.views.doAdminAction didn't return an HttpResponse object. It returned None instead.
[2020-08-18 07:37:22,376][uWSGIWorker1Core0:140159770849152][task_id:main.views][views.py:239][ERROR][Exception at doAdminAction: name 'acitonid' is not defined]
[2020-08-18 07:37:22,398][uWSGIWorker1Core0:140159770849152][task_id:django.request][log.py:224][ERROR][Internal Server Error: /admin_action]
Traceback (most recent call last):
  File "/usr/local/lib64/python3.8/site-packages/django/core/handlers/exception.py", line 47, in inner
    response = get_response(request)
  File "/usr/local/lib64/python3.8/site-packages/django/core/handlers/base.py", line 186, in _get_response
    self.check_response(response, callback)
  File "/usr/local/lib64/python3.8/site-packages/django/core/handlers/base.py", line 307, in check_response
    raise ValueError(
ValueError: The view main.views.doAdminAction didn't return an HttpResponse object. It returned None instead.
[2020-08-18 08:08:30,141][uWSGIWorker1Core0:140489500442496][task_id:django.request][log.py:224][ERROR][Internal Server Error: /admin]
Traceback (most recent call last):
  File "/usr/local/lib64/python3.8/site-packages/django/core/handlers/exception.py", line 47, in inner
    response = get_response(request)
  File "/usr/local/lib64/python3.8/site-packages/django/utils/deprecation.py", line 113, in __call__
    response = self.process_request(request)
  File "/usr/local/lib64/python3.8/site-packages/django/middleware/common.py", line 53, in process_request
    if self.should_redirect_with_slash(request):
  File "/usr/local/lib64/python3.8/site-packages/django/middleware/common.py", line 71, in should_redirect_with_slash
    not is_valid_path(request.path_info, urlconf) and
  File "/usr/local/lib64/python3.8/site-packages/django/urls/base.py", line 154, in is_valid_path
    resolve(path, urlconf)
  File "/usr/local/lib64/python3.8/site-packages/django/urls/base.py", line 25, in resolve
    return get_resolver(urlconf).resolve(path)
  File "/usr/local/lib64/python3.8/site-packages/django/urls/resolvers.py", line 545, in resolve
    for pattern in self.url_patterns:
  File "/usr/local/lib64/python3.8/site-packages/django/utils/functional.py", line 48, in __get__
    res = instance.__dict__[self.name] = self.func(instance)
  File "/usr/local/lib64/python3.8/site-packages/django/urls/resolvers.py", line 589, in url_patterns
    patterns = getattr(self.urlconf_module, "urlpatterns", self.urlconf_module)
  File "/usr/local/lib64/python3.8/site-packages/django/utils/functional.py", line 48, in __get__
    res = instance.__dict__[self.name] = self.func(instance)
  File "/usr/local/lib64/python3.8/site-packages/django/urls/resolvers.py", line 582, in urlconf_module
    return import_module(self.urlconf_name)
  File "/usr/lib64/python3.8/importlib/__init__.py", line 127, in import_module
    return _bootstrap._gcd_import(name[level:], package, level)
  File "<frozen importlib._bootstrap>", line 1014, in _gcd_import
  File "<frozen importlib._bootstrap>", line 991, in _find_and_load
  File "<frozen importlib._bootstrap>", line 975, in _find_and_load_unlocked
  File "<frozen importlib._bootstrap>", line 671, in _load_unlocked
  File "<frozen importlib._bootstrap_external>", line 783, in exec_module
  File "<frozen importlib._bootstrap>", line 219, in _call_with_frames_removed
  File "./webinfo/urls.py", line 3, in <module>
    from main import views as mainViews
  File "./main/views.py", line 250
    elif actionid='cha_ban':
                 ^
SyntaxError: invalid syntax
[2020-08-18 08:09:05,399][uWSGIWorker1Core0:139933645799296][task_id:main.views][views.py:261][ERROR][Exception at doAdminAction: 'str' object does not support item assignment]
[2020-08-18 08:09:05,425][uWSGIWorker1Core0:139933645799296][task_id:django.request][log.py:224][ERROR][Internal Server Error: /admin_action]
Traceback (most recent call last):
  File "/usr/local/lib64/python3.8/site-packages/django/core/handlers/exception.py", line 47, in inner
    response = get_response(request)
  File "/usr/local/lib64/python3.8/site-packages/django/core/handlers/base.py", line 186, in _get_response
    self.check_response(response, callback)
  File "/usr/local/lib64/python3.8/site-packages/django/core/handlers/base.py", line 307, in check_response
    raise ValueError(
ValueError: The view main.views.doAdminAction didn't return an HttpResponse object. It returned None instead.
[2020-08-18 08:10:39,536][uWSGIWorker1Core0:140317526704000][task_id:django.request][log.py:224][ERROR][Internal Server Error: /admin_action]
Traceback (most recent call last):
  File "/usr/local/lib64/python3.8/site-packages/django/core/handlers/exception.py", line 47, in inner
    response = get_response(request)
  File "/usr/local/lib64/python3.8/site-packages/django/utils/deprecation.py", line 113, in __call__
    response = self.process_request(request)
  File "/usr/local/lib64/python3.8/site-packages/django/middleware/common.py", line 53, in process_request
    if self.should_redirect_with_slash(request):
  File "/usr/local/lib64/python3.8/site-packages/django/middleware/common.py", line 71, in should_redirect_with_slash
    not is_valid_path(request.path_info, urlconf) and
  File "/usr/local/lib64/python3.8/site-packages/django/urls/base.py", line 154, in is_valid_path
    resolve(path, urlconf)
  File "/usr/local/lib64/python3.8/site-packages/django/urls/base.py", line 25, in resolve
    return get_resolver(urlconf).resolve(path)
  File "/usr/local/lib64/python3.8/site-packages/django/urls/resolvers.py", line 545, in resolve
    for pattern in self.url_patterns:
  File "/usr/local/lib64/python3.8/site-packages/django/utils/functional.py", line 48, in __get__
    res = instance.__dict__[self.name] = self.func(instance)
  File "/usr/local/lib64/python3.8/site-packages/django/urls/resolvers.py", line 589, in url_patterns
    patterns = getattr(self.urlconf_module, "urlpatterns", self.urlconf_module)
  File "/usr/local/lib64/python3.8/site-packages/django/utils/functional.py", line 48, in __get__
    res = instance.__dict__[self.name] = self.func(instance)
  File "/usr/local/lib64/python3.8/site-packages/django/urls/resolvers.py", line 582, in urlconf_module
    return import_module(self.urlconf_name)
  File "/usr/lib64/python3.8/importlib/__init__.py", line 127, in import_module
    return _bootstrap._gcd_import(name[level:], package, level)
  File "<frozen importlib._bootstrap>", line 1014, in _gcd_import
  File "<frozen importlib._bootstrap>", line 991, in _find_and_load
  File "<frozen importlib._bootstrap>", line 975, in _find_and_load_unlocked
  File "<frozen importlib._bootstrap>", line 671, in _load_unlocked
  File "<frozen importlib._bootstrap_external>", line 783, in exec_module
  File "<frozen importlib._bootstrap>", line 219, in _call_with_frames_removed
  File "./webinfo/urls.py", line 3, in <module>
    from main import views as mainViews
  File "./main/views.py", line 256
    c.extra = c.extra[:ind] + val + (c.extra[ind+1:] if ind<len(c.extra)-1)
                                                                          ^
SyntaxError: invalid syntax
[2020-08-18 08:15:02,192][uWSGIWorker1Core0:140489194164096][task_id:django.request][log.py:224][ERROR][Internal Server Error: /article-10/]
Traceback (most recent call last):
  File "/usr/local/lib64/python3.8/site-packages/django/core/handlers/exception.py", line 47, in inner
    response = get_response(request)
  File "/usr/local/lib64/python3.8/site-packages/django/core/handlers/base.py", line 179, in _get_response
    response = wrapped_callback(request, *callback_args, **callback_kwargs)
  File "./article/views.py", line 51, in showArticlePage
    showuser = (category.extra[0]=='1')
NameError: name 'category' is not defined
[2020-08-18 08:16:02,174][uWSGIWorker1Core0:139747837464448][task_id:django.request][log.py:224][ERROR][Internal Server Error: /article-10/]
Traceback (most recent call last):
  File "/usr/local/lib64/python3.8/site-packages/django/core/handlers/exception.py", line 47, in inner
    response = get_response(request)
  File "/usr/local/lib64/python3.8/site-packages/django/core/handlers/base.py", line 179, in _get_response
    response = wrapped_callback(request, *callback_args, **callback_kwargs)
  File "./article/views.py", line 55, in showArticlePage
    author_ids = getAuthorList(forum_id)
NameError: name 'forum_id' is not defined
[2020-08-18 09:29:03,377][uWSGIWorker1Core0:140315161300864][task_id:article.views][views.py:159][ERROR][hour must be in 0..23]
[2020-08-18 09:31:53,140][uWSGIWorker1Core0:140689333493632][task_id:django.request][log.py:224][ERROR][Internal Server Error: /list-article]
Traceback (most recent call last):
  File "/usr/local/lib64/python3.8/site-packages/django/core/handlers/exception.py", line 47, in inner
    response = get_response(request)
  File "/usr/local/lib64/python3.8/site-packages/django/core/handlers/base.py", line 179, in _get_response
    response = wrapped_callback(request, *callback_args, **callback_kwargs)
  File "./article/views.py", line 185, in showArticleList
    if article.create_date < month_start or article.create_date > month_end:
TypeError: can't compare offset-naive and offset-aware datetimes
[2020-08-18 09:37:46,281][uWSGIWorker1Core0:139931209932672][task_id:django.request][log.py:224][ERROR][Internal Server Error: /list-article]
Traceback (most recent call last):
  File "/usr/local/lib64/python3.8/site-packages/django/core/handlers/exception.py", line 47, in inner
    response = get_response(request)
  File "/usr/local/lib64/python3.8/site-packages/django/utils/deprecation.py", line 113, in __call__
    response = self.process_request(request)
  File "/usr/local/lib64/python3.8/site-packages/django/middleware/common.py", line 53, in process_request
    if self.should_redirect_with_slash(request):
  File "/usr/local/lib64/python3.8/site-packages/django/middleware/common.py", line 71, in should_redirect_with_slash
    not is_valid_path(request.path_info, urlconf) and
  File "/usr/local/lib64/python3.8/site-packages/django/urls/base.py", line 154, in is_valid_path
    resolve(path, urlconf)
  File "/usr/local/lib64/python3.8/site-packages/django/urls/base.py", line 25, in resolve
    return get_resolver(urlconf).resolve(path)
  File "/usr/local/lib64/python3.8/site-packages/django/urls/resolvers.py", line 545, in resolve
    for pattern in self.url_patterns:
  File "/usr/local/lib64/python3.8/site-packages/django/utils/functional.py", line 48, in __get__
    res = instance.__dict__[self.name] = self.func(instance)
  File "/usr/local/lib64/python3.8/site-packages/django/urls/resolvers.py", line 589, in url_patterns
    patterns = getattr(self.urlconf_module, "urlpatterns", self.urlconf_module)
  File "/usr/local/lib64/python3.8/site-packages/django/utils/functional.py", line 48, in __get__
    res = instance.__dict__[self.name] = self.func(instance)
  File "/usr/local/lib64/python3.8/site-packages/django/urls/resolvers.py", line 582, in urlconf_module
    return import_module(self.urlconf_name)
  File "/usr/lib64/python3.8/importlib/__init__.py", line 127, in import_module
    return _bootstrap._gcd_import(name[level:], package, level)
  File "<frozen importlib._bootstrap>", line 1014, in _gcd_import
  File "<frozen importlib._bootstrap>", line 991, in _find_and_load
  File "<frozen importlib._bootstrap>", line 975, in _find_and_load_unlocked
  File "<frozen importlib._bootstrap>", line 671, in _load_unlocked
  File "<frozen importlib._bootstrap_external>", line 783, in exec_module
  File "<frozen importlib._bootstrap>", line 219, in _call_with_frames_removed
  File "./webinfo/urls.py", line 4, in <module>
    from article import views as articleViews
  File "./article/views.py", line 155
    else:
    ^
SyntaxError: invalid syntax
[2020-08-21 09:58:26,120][uWSGIWorker1Core0:140327154495360][task_id:django.request][log.py:224][ERROR][Internal Server Error: /admin]
Traceback (most recent call last):
  File "/usr/local/lib64/python3.8/site-packages/django/core/handlers/exception.py", line 47, in inner
    response = get_response(request)
  File "/usr/local/lib64/python3.8/site-packages/django/core/handlers/base.py", line 179, in _get_response
    response = wrapped_callback(request, *callback_args, **callback_kwargs)
  File "./main/views.py", line 158, in showAdmin
    'cover_img': '/s/'+coverimg,
NameError: name 'coverimg' is not defined
[2020-08-21 09:58:43,717][uWSGIWorker1Core0:140327154495360][task_id:django.request][log.py:224][ERROR][Internal Server Error: /admin]
Traceback (most recent call last):
  File "/usr/local/lib64/python3.8/site-packages/django/core/handlers/exception.py", line 47, in inner
    response = get_response(request)
  File "/usr/local/lib64/python3.8/site-packages/django/core/handlers/base.py", line 179, in _get_response
    response = wrapped_callback(request, *callback_args, **callback_kwargs)
  File "./main/views.py", line 158, in showAdmin
    'cover_img': '/s/'+_.coverimg,
NameError: name 'coverimg' is not defined
[2020-08-21 14:44:01,824][uWSGIWorker1Core0:140000393539456][task_id:main.views][views.py:275][ERROR][Exception at doAdminAction: 'NoneType' object has no attribute 'name']
[2020-08-21 14:44:01,853][uWSGIWorker1Core0:140000393539456][task_id:django.request][log.py:224][ERROR][Internal Server Error: /admin_action]
Traceback (most recent call last):
  File "/usr/local/lib64/python3.8/site-packages/django/core/handlers/exception.py", line 47, in inner
    response = get_response(request)
  File "/usr/local/lib64/python3.8/site-packages/django/core/handlers/base.py", line 186, in _get_response
    self.check_response(response, callback)
  File "/usr/local/lib64/python3.8/site-packages/django/core/handlers/base.py", line 307, in check_response
    raise ValueError(
ValueError: The view main.views.doAdminAction didn't return an HttpResponse object. It returned None instead.
[2020-08-21 14:51:29,085][uWSGIWorker1Core0:140000393539456][task_id:main.views][views.py:275][ERROR][Exception at doAdminAction: 'NoneType' object has no attribute 'name']
[2020-08-21 14:51:29,109][uWSGIWorker1Core0:140000393539456][task_id:django.request][log.py:224][ERROR][Internal Server Error: /admin_action]
Traceback (most recent call last):
  File "/usr/local/lib64/python3.8/site-packages/django/core/handlers/exception.py", line 47, in inner
    response = get_response(request)
  File "/usr/local/lib64/python3.8/site-packages/django/core/handlers/base.py", line 186, in _get_response
    self.check_response(response, callback)
  File "/usr/local/lib64/python3.8/site-packages/django/core/handlers/base.py", line 307, in check_response
    raise ValueError(
ValueError: The view main.views.doAdminAction didn't return an HttpResponse object. It returned None instead.
[2020-08-21 14:53:16,495][uWSGIWorker1Core0:140000393539456][task_id:main.views][views.py:275][ERROR][Exception at doAdminAction: 'NoneType' object has no attribute 'name']
[2020-08-21 14:53:16,521][uWSGIWorker1Core0:140000393539456][task_id:django.request][log.py:224][ERROR][Internal Server Error: /admin_action]
Traceback (most recent call last):
  File "/usr/local/lib64/python3.8/site-packages/django/core/handlers/exception.py", line 47, in inner
    response = get_response(request)
  File "/usr/local/lib64/python3.8/site-packages/django/core/handlers/base.py", line 186, in _get_response
    self.check_response(response, callback)
  File "/usr/local/lib64/python3.8/site-packages/django/core/handlers/base.py", line 307, in check_response
    raise ValueError(
ValueError: The view main.views.doAdminAction didn't return an HttpResponse object. It returned None instead.
[2020-08-21 14:53:24,490][uWSGIWorker1Core0:140000393539456][task_id:main.views][views.py:275][ERROR][Exception at doAdminAction: 'NoneType' object has no attribute 'name']
[2020-08-21 14:53:24,514][uWSGIWorker1Core0:140000393539456][task_id:django.request][log.py:224][ERROR][Internal Server Error: /admin_action]
Traceback (most recent call last):
  File "/usr/local/lib64/python3.8/site-packages/django/core/handlers/exception.py", line 47, in inner
    response = get_response(request)
  File "/usr/local/lib64/python3.8/site-packages/django/core/handlers/base.py", line 186, in _get_response
    self.check_response(response, callback)
  File "/usr/local/lib64/python3.8/site-packages/django/core/handlers/base.py", line 307, in check_response
    raise ValueError(
ValueError: The view main.views.doAdminAction didn't return an HttpResponse object. It returned None instead.
[2020-08-21 14:53:57,541][uWSGIWorker1Core0:140000393539456][task_id:main.views][views.py:275][ERROR][Exception at doAdminAction: 'NoneType' object has no attribute 'name']
[2020-08-21 14:53:57,564][uWSGIWorker1Core0:140000393539456][task_id:django.request][log.py:224][ERROR][Internal Server Error: /admin_action]
Traceback (most recent call last):
  File "/usr/local/lib64/python3.8/site-packages/django/core/handlers/exception.py", line 47, in inner
    response = get_response(request)
  File "/usr/local/lib64/python3.8/site-packages/django/core/handlers/base.py", line 186, in _get_response
    self.check_response(response, callback)
  File "/usr/local/lib64/python3.8/site-packages/django/core/handlers/base.py", line 307, in check_response
    raise ValueError(
ValueError: The view main.views.doAdminAction didn't return an HttpResponse object. It returned None instead.
[2020-08-21 14:54:51,012][uWSGIWorker1Core0:140000393539456][task_id:main.views][views.py:275][ERROR][Exception at doAdminAction: 'NoneType' object has no attribute 'name']
[2020-08-21 14:54:51,035][uWSGIWorker1Core0:140000393539456][task_id:django.request][log.py:224][ERROR][Internal Server Error: /admin_action]
Traceback (most recent call last):
  File "/usr/local/lib64/python3.8/site-packages/django/core/handlers/exception.py", line 47, in inner
    response = get_response(request)
  File "/usr/local/lib64/python3.8/site-packages/django/core/handlers/base.py", line 186, in _get_response
    self.check_response(response, callback)
  File "/usr/local/lib64/python3.8/site-packages/django/core/handlers/base.py", line 307, in check_response
    raise ValueError(
ValueError: The view main.views.doAdminAction didn't return an HttpResponse object. It returned None instead.
[2020-08-21 14:55:43,159][uWSGIWorker1Core0:139970374541184][task_id:main.views][views.py:272][ERROR][on]
[2020-08-21 14:57:13,539][uWSGIWorker1Core0:139970374541184][task_id:main.views][views.py:272][ERROR][on]
[2020-08-21 14:57:30,643][uWSGIWorker1Core0:140115547975552][task_id:django.request][log.py:224][ERROR][Internal Server Error: /admin]
Traceback (most recent call last):
  File "/usr/local/lib64/python3.8/site-packages/django/core/handlers/exception.py", line 47, in inner
    response = get_response(request)
  File "/usr/local/lib64/python3.8/site-packages/django/core/handlers/base.py", line 179, in _get_response
    response = wrapped_callback(request, *callback_args, **callback_kwargs)
  File "./main/views.py", line 159, in showAdmin
    'name_white': _.name_white,
AttributeError: 'Category' object has no attribute 'name_white'
[2020-08-21 14:58:09,937][uWSGIWorker1Core0:140115547975552][task_id:django.request][log.py:224][ERROR][Internal Server Error: /admin]
Traceback (most recent call last):
  File "/usr/local/lib64/python3.8/site-packages/django/core/handlers/exception.py", line 47, in inner
    response = get_response(request)
  File "/usr/local/lib64/python3.8/site-packages/django/core/handlers/base.py", line 179, in _get_response
    response = wrapped_callback(request, *callback_args, **callback_kwargs)
  File "./main/views.py", line 159, in showAdmin
    'name_white': _.title_white,
AttributeError: 'Category' object has no attribute 'name_white'
